Workbook

Sheet Assumptions
A1: A&H Fleet OS SaaS - unit economics assumptions (yellow cells are editable)
A2: Cost case (1=Low, 2=Base, 3=High) | B2: 2
A3: Selected case | B3: =CHOOSE(B2,"Low","Base","High") -> Base
A5: Assumption | B5: Low | C5: Base | D5: High | E5: SELECTED | F5: Unit | G5: Note
A6: Loads per truck per week | B6: 4 | C6: 4 | D6: 4 | E6: =CHOOSE($B$2,B6,C6,D6) -> 4 | F6: loads | G6: Given by Abdel
A7: Weeks per month | B7: 4.33 | C7: 4.33 | D7: 4.33 | E7: =CHOOSE($B$2,B7,C7,D7) -> 4.33
A8: Share of loads booked through AI Dispatcher | B8: 1 | C8: 1 | D8: 1 | E8: =CHOOSE($B$2,B8,C8,D8) -> 1 | F8: % | G8: Stress case = 100% (Abdel's assumption). Real adoption likely 30-70%
A9: AI voice minutes per booked load (all calls incl. voicemail/hold) | B9: 5 | C9: 9 | D9: 18 | E9: =CHOOSE($B$2,B9,C9,D9) -> 9 | F9: min | G9: Base ~3 calls x 3 min. High = long negotiations/holds
A10: All-in voice cost per minute (Vapi $0.05 + STT + LLM + TTS + Twilio $0.014) | B10: 0.1 | C10: 0.16 | D10: 0.25 | E10: =CHOOSE($B$2,B10,C10,D10) -> 0.16 | F10: $/min | G10: Third-party estimates range $0.07-$0.31/min; verify on vendor pages
A11: LLM input tokens per booked load (email, ratecon/BOL/POD parse, matching, call summaries, retries) | B11: 60000 | C11: 120000 | D11: 250000 | E11: =CHOOSE($B$2,B11,C11,D11) -> 120000 | F11: tokens | G11: Estimate; measure in pilot
A12: LLM output tokens per booked load | B12: 8000 | C12: 17000 | D12: 40000 | E12: =CHOOSE($B$2,B12,C12,D12) -> 17000 | F12: tokens | G12: Estimate; measure in pilot
A13: Blended LLM input price per 1M tokens | B13: 0.1 | C13: 0.64 | D13: 2 | E13: =CHOOSE($B$2,B13,C13,D13) -> 0.64 | F13: $/1M | G13: Low=Haiku 5.5 ($0.10). Base=80% Gemini 2.5 Flash ($0.30)+20% Sonnet 5.5 ($2). High=all Sonnet 5.5
A14: Blended LLM output price per 1M tokens | B14: 0.5 | C14: 4 | D14: 10 | E14: =CHOOSE($B$2,B14,C14,D14) -> 4 | F14: $/1M | G14: Low=Haiku 5.5 ($0.50). Base=80% Flash ($2.50)+20% Sonnet 5.5 ($10). High=all Sonnet 5.5
A15: SMS per booked load (driver alerts, broker/driver confirmations) | B15: 3 | C15: 5 | D15: 10 | E15: =CHOOSE($B$2,B15,C15,D15) -> 5 | F15: msgs
A16: Cost per SMS segment (Twilio $0.0079 + ~$0.003 carrier fee) | B16: 0.0109 | C16: 0.0109 | D16: 0.0109 | E16: =CHOOSE($B$2,B16,C16,D16) -> 0.0109 | F16: $ | G16: 10DLC registration extra
A17: Emails per booked load (outreach, replies, BOL/POD notices, invoice) | B17: 6 | C17: 10 | D17: 20 | E17: =CHOOSE($B$2,B17,C17,D17) -> 10 | F17: emails
A18: Cost per email (Resend overage $0.90/1k) | B18: 0.0009 | C18: 0.0009 | D18: 0.0009 | E18: =CHOOSE($B$2,B18,C18,D18) -> 0.0009 | F18: $
A19: Maps/distance/geocoding per booked load | B19: 0.01 | C19: 0.03 | D19: 0.06 | E19: =CHOOSE($B$2,B19,C19,D19) -> 0.03 | F19: $ | G19: Google Maps APIs
A20: Other variable cost per truck/month (DVIR AI photos, push, storage growth, ELD sync) | B20: 0.2 | C20: 0.5 | D20: 1.5 | E20: =CHOOSE($B$2,B20,C20,D20) -> 0.5 | F20: $ | G20: DVIR photo AI ~ $0.15/truck/mo; storage grows with retention
A21: Payment processing % of revenue (card 2.9% / ACH 0.8%, blended) | B21: 0.015 | C21: 0.025 | D21: 0.032 | E21: =CHOOSE($B$2,B21,C21,D21) -> 0.025 | F21: % | G21: Stripe
A22: Payment processing fixed fee per month | B22: 0.3 | C22: 0.3 | D22: 0.3 | E22: =CHOOSE($B$2,B22,C22,D22) -> 0.3 | F22: $
A23: Recruiting variable cost per engaged lead (SMS cadence + 2 AI calls + LLM) | B23: 0.6 | C23: 1.2 | D23: 3 | E23: =CHOOSE($B$2,B23,C23,D23) -> 1.2 | F23: $ | G23: Excludes background checks (pass-through)
A25: Fixed per-tenant costs by carrier size ($/month)
A26: Item | B26: Low | C26: Base | D26: High | E26: SELECTED
A27: Infra - 2 trucks | B27: 1 | C27: 3 | D27: 6 | E27: =CHOOSE($B$2,B27,C27,D27) -> 3
A28: Infra - 10 trucks | B28: 3 | C28: 6 | D28: 12 | E28: =CHOOSE($B$2,B28,C28,D28) -> 6
A29: Infra - 25 trucks | B29: 6 | C29: 12 | D29: 25 | E29: =CHOOSE($B$2,B29,C29,D29) -> 12
A30: Infra - 100 trucks | B30: 20 | C30: 40 | D30: 90 | E30: =CHOOSE($B$2,B30,C30,D30) -> 40
A31: Support+success - 2 trucks | B31: 3 | C31: 8 | D31: 20 | E31: =CHOOSE($B$2,B31,C31,D31) -> 8
A32: Support+success - 10 trucks | B32: 15 | C32: 30 | D32: 70 | E32: =CHOOSE($B$2,B32,C32,D32) -> 30
A33: Support+success - 25 trucks | B33: 40 | C33: 80 | D33: 160 | E33: =CHOOSE($B$2,B33,C33,D33) -> 80
A34: Support+success - 100 trucks | B34: 200 | C34: 400 | D34: 800 | E34: =CHOOSE($B$2,B34,C34,D34) -> 400
A36: Engaged recruiting leads per month (when Recruiting add-on is on)
A37: Leads/month - 2 trucks | E37: 10
A38: Leads/month - 10 trucks | E38: 40
A39: Leads/month - 25 trucks | E39: 100
A40: Leads/month - 100 trucks | E40: 350

Sheet Case_Comparison
A1: Gross margin by cost case (static values from the model; re-run by changing Assumptions!B2)
A3: Metric | B3: Price book | C3: Cost case | D3: 2 trucks | E3: 10 trucks | F3: 25 trucks | G3: 100 trucks
A4: AI cost per booked load | B4: n/a | C4: Low | D4: 0.5581 | E4: 0.5581 | F4: 0.5581 | G4: 0.5581
A5: AI cost per booked load | B5: n/a | C5: Base | D5: 1.6783 | E5: 1.6783 | F5: 1.6783 | G5: 1.6783
A6: AI cost per booked load | B6: n/a | C6: High | D6: 5.587 | E6: 5.587 | F6: 5.587 | G6: 5.587
A7: Gross margin platform only | B7: v1 first draft | C7: Low | D7: 0.86448718 | E7: 0.84875839 | F7: 0.83842857 | G7: 0.8248
A8: Gross margin platform only | B8: v1 first draft | C8: Base | D8: 0.65961538 | E8: 0.69781879 | F8: 0.67557143 | G8: 0.64813333
A9: Gross margin platform only | B9: v1 first draft | C9: High | D9: 0.21671795 | E9: 0.31497987 | F9: 0.33142857 | G9: 0.27446667
A10: Gross margin platform + AI Dispatcher | B10: v1 first draft | C10: Low | D10: 0.78133403 | E10: 0.47200474 | F10: 0.42399406 | G10: 0.43434337
A11: Gross margin platform + AI Dispatcher | B11: v1 first draft | C11: Base | D11: 0.3780821 | E11: -0.48105947 | F11: -0.61730927 | G11: -0.57492043
A12: Gross margin platform + AI Dispatcher | B12: v1 first draft | C12: High | D12: -0.92042102 | E12: -3.702914 | F12: -4.0913087 | G12: -3.9215812
A13: Gross margin platform + AI + Recruiting | B13: v1 first draft | C13: Low | D13: 0.846601 | E13: 0.55392073 | F13: 0.41681375 | G13: 0.3664697
A14: Gross margin platform + AI + Recruiting | B14: v1 first draft | C14: Base | D14: 0.59510916 | E14: -0.18702312 | F14: -0.55671909 | G14: -0.6912806
A15: Gross margin platform + AI + Recruiting | B15: v1 first draft | C15: High | D15: -0.19713217 | E15: -2.6557566 | F15: -3.7679482 | G15: -4.1686265
... A33: GROSS PROFIT platform + AI Dispatcher | B33: v1 first draft | C33: High | D33: -108.60968 | E33: -844.2644 | F33: -2136.4814 | G33: -8595.3216

Sheet PriceBook
A1: Price books (hypotheses - yellow cells editable)
A3: Item | B3: v1 (first draft) | C3: v2 (proposed) | D3: Note
A4: Starter flat monthly price | B4: 39 | C4: 79 | D4: v1: <=3 trucks; v2: <=5 trucks
A5: Starter included trucks | B5: 3 | C5: 5
A6: Starter price per extra truck | B6: 9 | C6: 12
A7: Fleet per-truck price | B7: 14 | C7: 19 | D7: 6-50 trucks
A8: Fleet monthly minimum | B8: 149 | C8: 199
A9: Enterprise per-truck price | B9: 10.5 | C9: 14 | D9: 51+ trucks
A10: Enterprise monthly minimum | B10: 1500 | C10: 1500 | D10: plus one-time onboarding fee (not modeled)
A11: AI Dispatcher base fee / month | B11: 79 | C11: 49 | D11: v1 included 200 actions
A12: AI Dispatcher included booked loads | B12: 200 | C12: 0 | D12: v1 only
A13: v1 price per booked load beyond included | B13: 0.4 | C13: 0 | D13: v1 only
A14: v2 price per booked load, first 200/month | B14: 0 | C14: 6 | D14: v2 only
A15: v2 price per booked load, 201-1000 | B15: 0 | C15: 4.5 | D15: v2 only
A16: v2 price per booked load, above 1000 | B16: 0 | C16: 3.5 | D16: v2 only
A17: Recruiting add-on base fee / month | B17: 99 | C17: 149
A18: Recruiting price per engaged lead | B18: 0 | C18: 2.5 | D18: v1 had metered usage unspecified

Sheet Model
A1: Monthly economics per carrier size (uses SELECTED cost case on Assumptions sheet)
A2: ="Cost case: "&Assumptions!B3 -> Cost case: Base
A4: Line | B4: Unit | C4: 2 trucks | D4: 10 trucks | E4: 25 trucks | F4: 100 trucks
A5: Trucks | B5: # | C5: 2 | D5: 10 | E5: 25 | F5: 100
A6: Loads per month (all) | B6: loads | C6: =C5*Assumptions!$E$6*Assumptions!$E$7 -> 34.64 | D6: =D5*Assumptions!$E$6*Assumptions!$E$7 -> 173.2 | E6: =E5*Assumptions!$E$6*Assumptions!$E$7 -> 433 | F6: =F5*Assumptions!$E$6*Assumptions!$E$7 -> 1732
A7: AI-booked loads per month | B7: loads | C7: =C6*Assumptions!$E$8 -> 34.64 | D7: =D6*Assumptions!$E$8 -> 173.2 | E7: =E6*Assumptions!$E$8 -> 433 | F7: =F6*Assumptions!$E$8 -> 1732
A9: Voice cost (AI calls) | B9: $/mo | C9: =C7*Assumptions!$E$9*Assumptions!$E$10 -> 49.8816 | D9: =D7*Assumptions!$E$9*Assumptions!$E$10 -> 249.408 | E9: =E7*Assumptions!$E$9*Assumptions!$E$10 -> 623.52 | F9: =F7*Assumptions!$E$9*Assumptions!$E$10 -> 2494.08
A10: LLM token cost | B10: $/mo | C10: =C7*(Assumptions!$E$11*Assumptions!$E$13+Assumptions!$E$12*Assumptions!$E$14)/1000000 -> 5.015872 | D10: =D7*(Assumptions!$E$11*Assumptions!$E$13+Assumptions!$E$12*Assumptions!$E$14)/1000000 -> 25.07936 | E10: =E7*(Assumptions!$E$11*Assumptions!$E$13+Assumptions!$E$12*Assumptions!$E$14)/1000000 -> 62.6984 | F10: =F7*(Assumptions!$E$11*Assumptions!$E$13+Assumptions!$E$12*Assumptions!$E$14)/1000000 -> 250.7936
A11: SMS cost | B11: $/mo | C11: =C7*Assumptions!$E$15*Assumptions!$E$16 -> 1.88788 | D11: =D7*Assumptions!$E$15*Assumptions!$E$16 -> 9.4394 | E11: =E7*Assumptions!$E$15*Assumptions!$E$16 -> 23.5985 | F11: =F7*Assumptions!$E$15*Assumptions!$E$16 -> 94.394
A12: Email cost | B12: $/mo | C12: =C7*Assumptions!$E$17*Assumptions!$E$18 -> 0.31176 | D12: =D7*Assumptions!$E$17*Assumptions!$E$18 -> 1.5588 | E12: =E7*Assumptions!$E$17*Assumptions!$E$18 -> 3.897 | F12: =F7*Assumptions!$E$17*Assumptions!$E$18 -> 15.588
A13: Maps cost | B13: $/mo | C13: =C7*Assumptions!$E$19 -> 1.0392 | D13: =D7*Assumptions!$E$19 -> 5.196 | E13: =E7*Assumptions!$E$19 -> 12.99 | F13: =F7*Assumptions!$E$19 -> 51.96
A14: AI dispatcher variable cost total | B14: $/mo | C14: =SUM(C9:C13) -> 58.136312 | D14: =SUM(D9:D13) -> 290.68156 | E14: =SUM(E9:E13) -> 726.7039 | F14: =SUM(F9:F13) -> 2906.8156
A15: AI cost per booked load | B15: $/load | C15: =IF(C7=0,0,C14/C7) -> 1.6783 | D15: =IF(D7=0,0,D14/D7) -> 1.6783 | E15: =IF(E7=0,0,E14/E7) -> 1.6783 | F15: =IF(F7=0,0,F14/F7) -> 1.6783
A17: Other variable cost (DVIR AI, push, storage) | B17: $/mo | C17: =C5*Assumptions!$E$20 -> 1 | D17: =D5*Assumptions!$E$20 -> 5 | E17: =E5*Assumptions!$E$20 -> 12.5 | F17: =F5*Assumptions!$E$20 -> 50
A18: Infra share (database, storage, egress) | B18: $/mo | C18: =Assumptions!$E$27 -> 3 | D18: =Assumptions!$E$28 -> 6 | E18: =Assumptions!$E$29 -> 12 | F18: =Assumptions!$E$30 -> 40
A19: Support + success allocation | B19: $/mo | C19: =Assumptions!$E$31 -> 8 | D19: =Assumptions!$E$32 -> 30 | E19: =Assumptions!$E$33 -> 80 | F19: =Assumptions!$E$34 -> 400
A21: [v1 first-draft prices] Platform subscription revenue | B21: $/mo | C21: =PriceBook!$B$4+PriceBook!$B$6*MAX(0,C5-PriceBook!$B$5) -> 39 | D21: =MAX(PriceBook!$B$8,PriceBook!$B$7*D5) -> 149 | E21: =MAX(PriceBook!$B$8,PriceBook!$B$7*E5) -> 350 | F21: =MAX(PriceBook!$B$10,PriceBook!$B$9*F5) -> 1500
A22: [v1 first-draft prices] AI Dispatcher add-on revenue | B22: $/mo | C22: =PriceBook!$B$11+PriceBook!$B$13*MAX(0,C7-PriceBook!$B$12) -> 79 | D22: =PriceBook!$B$11+PriceBook!$B$13*MAX(0,D7-PriceBook!$B$12) -> 79 | E22: =PriceBook!$B$11+PriceBook!$B$13*MAX(0,E7-PriceBook!$B$12) -> 172.2 | F22: =PriceBook!$B$11+PriceBook!$B$13*MAX(0,F7-PriceBook!$B$12) -> 691.8
A23: [v1 first-draft prices] Recruiting add-on revenue | B23: $/mo | C23: =PriceBook!$B$17+PriceBook!$B$18*Assumptions!$E$37 -> 99 | D23: =PriceBook!$B$17+PriceBook!$B$18*Assumptions!$E$38 -> 99 | E23: =PriceBook!$B$17+PriceBook!$B$18*Assumptions!$E$39 -> 99 | F23: =PriceBook!$B$17+PriceBook!$B$18*Assumptions!$E$40 -> 99
A24: payment fees (platform only) | B24: $/mo | C24: =Assumptions!$E$21*C21+Assumptions!$E$22 -> 1.275 | D24: =Assumptions!$E$21*D21+Assumptions!$E$22 -> 4.025 | E24: =Assumptions!$E$21*E21+Assumptions!$E$22 -> 9.05 | F24: =Assumptions!$E$21*F21+Assumptions!$E$22 -> 37.8
A25: payment fees (platform + AI) | B25: $/mo | C25: =Assumptions!$E$21*(C21+C22)+Assumptions!$E$22 -> 3.25 | D25: =Assumptions!$E$21*(D21+D22)+Assumptions!$E$22 -> 6 | E25: =Assumptions!$E$21*(E21+E22)+Assumptions!$E$22 -> 13.355 | F25: =Assumptions!$E$21*(F21+F22)+Assumptions!$E$22 -> 55.095
A26: payment fees (all add-ons) | B26: $/mo | C26: =Assumptions!$E$21*(C21+C22+C23)+Assumptions!$E$22 -> 5.725 | D26: =Assumptions!$E$21*(D21+D22+D23)+Assumptions!$E$22 -> 8.475 | E26: =Assumptions!$E$21*(E21+E22+E23)+Assumptions!$E$22 -> 15.83 | F26: =Assumptions!$E$21*(F21+F22+F23)+Assumptions!$E$22 -> 57.57
A27: GROSS PROFIT platform only | B27: $/mo | C27: =C21-(C17+C18+C19)-C24 -> 25.725 | D27: =D21-(D17+D18+D19)-D24 -> 103.975 | E27: =E21-(E17+E18+E19)-E24 -> 236.45 | F27: =F21-(F17+F18+F19)-F24 -> 972.2
A28: Gross margin platform only | B28: % | C28: =C27/C21 -> 0.65961538 | D28: =D27/D21 -> 0.69781879 | E28: =E27/E21 -> 0.67557143 | F28: =F27/F21 -> 0.64813333
A29: GROSS PROFIT platform + AI Dispatcher | B29: $/mo | C29: =C21+C22-(C17+C18+C19)-C14-C25 -> 44.613688 | D29: =D21+D22-(D17+D18+D19)-D14-D25 -> -109.68156 | E29: =E21+E22-(E17+E18+E19)-E14-E25 -> -322.3589 | F29: =F21+F22-(F17+F18+F19)-F14-F25 -> -1260.1106
A30: Gross margin platform + AI Dispatcher | B30: % | C30: =C29/(C21+C22) -> 0.3780821 | D30: =D29/(D21+D22) -> -0.48105947 | E30: =E29/(E21+E22) -> -0.61730927 | F30: =F29/(F21+F22) -> -0.57492043
A31: GROSS PROFIT platform + AI + Recruiting | B31: $/mo | C31: =C21+C22+C23-(C17+C18+C19)-C14-C51-C26 -> 129.13869 | D31: =D21+D22+D23-(D17+D18+D19)-D14-D51-D26 -> -61.15656 | E31: =E21+E22+E23-(E17+E18+E19)-E14-E51-E26 -> -345.8339 | F31: =F21+F22+F23-(F17+F18+F19)-F14-F51-F26 -> -1583.5856
A32: Gross margin platform + AI + Recruiting | B32: % | C32: =C31/C33 -> 0.59510916 | D32: =D31/D33 -> -0.18702312 | E32: =E31/E33 -> -0.55671909 | F32: =F31/F33 -> -0.6912806
A33: Total revenue (platform + AI + Recruiting) | B33: $/mo | C33: =C21+C22+C23 -> 217 | D33: =D21+D22+D23 -> 327 | E33: =E21+E22+E23 -> 621.2 | F33: =F21+F22+F23 -> 2290.8
A34: Total cost (platform + AI + Recruiting) | B34: $/mo | C34: =(C17+C18+C19)+C14+C51+C26 -> 87.861312 | D34: =(D17+D18+D19)+D14+D51+D26 -> 388.15656 | E34: =(E17+E18+E19)+E14+E51+E26 -> 967.0339 | F34: =(F17+F18+F19)+F14+F51+F26 -> 3874.3856
A36: [v2 proposed prices] Platform subscription revenue | B36: $/mo | C36: =PriceBook!$C$4+PriceBook!$C$6*MAX(0,C5-PriceBook!$C$5) -> 79 | D36: =MAX(PriceBook!$C$8,PriceBook!$C$7*D5) -> 199 | E36: =MAX(PriceBook!$C$8,PriceBook!$C$7*E5) -> 475 | F36: =MAX(PriceBook!$C$10,PriceBook!$C$9*F5) -> 1500
A37: [v2 proposed prices] AI Dispatcher add-on revenue | B37: $/mo | C37: =PriceBook!$C$11+PriceBook!$C$14*MIN(C7,200)+PriceBook!$C$15*MAX(0,MIN(C7,1000)-200)+PriceBook!$C$16*MAX(0,C7-1000) -> 256.84 | D37: =PriceBook!$C$11+PriceBook!$C$14*MIN(D7,200)+PriceBook!$C$15*MAX(0,MIN(D7,1000)-200)+PriceBook!$C$16*MAX(0,D7-1000) -> 1088.2 | E37: =PriceBook!$C$11+PriceBook!$C$14*MIN(E7,200)+PriceBook!$C$15*MAX(0,MIN(E7,1000)-200)+PriceBook!$C$16*MAX(0,E7-1000) -> 2297.5 | F37: =PriceBook!$C$11+PriceBook!$C$14*MIN(F7,200)+PriceBook!$C$15*MAX(0,MIN(F7,1000)-200)+PriceBook!$C$16*MAX(0,F7-1000) -> 7411
A38: [v2 proposed prices] Recruiting add-on revenue | B38: $/mo | C38: =PriceBook!$C$17+PriceBook!$C$18*Assumptions!$E$37 -> 174 | D38: =PriceBook!$C$17+PriceBook!$C$18*Assumptions!$E$38 -> 249 | E38: =PriceBook!$C$17+PriceBook!$C$18*Assumptions!$E$39 -> 399 | F38: =PriceBook!$C$17+PriceBook!$C$18*Assumptions!$E$40 -> 1024
A39: payment fees (platform only) | B39: $/mo | C39: =Assumptions!$E$21*C36+Assumptions!$E$22 -> 2.275 | D39: =Assumptions!$E$21*D36+Assumptions!$E$22 -> 5.275 | E39: =Assumptions!$E$21*E36+Assumptions!$E$22 -> 12.175 | F39: =Assumptions!$E$21*F36+Assumptions!$E$22 -> 37.8
A40: payment fees (platform + AI) | B40: $/mo | C40: =Assumptions!$E$21*(C36+C37)+Assumptions!$E$22 -> 8.696 | D40: =Assumptions!$E$21*(D36+D37)+Assumptions!$E$22 -> 32.48 | E40: =Assumptions!$E$21*(E36+E37)+Assumptions!$E$22 -> 69.6125 | F40: =Assumptions!$E$21*(F36+F37)+Assumptions!$E$22 -> 223.075
A41: payment fees (all add-ons) | B41: $/mo | C41: =Assumptions!$E$21*(C36+C37+C38)+Assumptions!$E$22 -> 13.046 | D41: =Assumptions!$E$21*(D36+D37+D38)+Assumptions!$E$22 -> 38.705 | E41: =Assumptions!$E$21*(E36+E37+E38)+Assumptions!$E$22 -> 79.5875 | F41: =Assumptions!$E$21*(F36+F37+F38)+Assumptions!$E$22 -> 248.675
A42: GROSS PROFIT platform only | B42: $/mo | C42: =C36-(C17+C18+C19)-C39 -> 64.725 | D42: =D36-(D17+D18+D19)-D39 -> 152.725 | E42: =E36-(E17+E18+E19)-E39 -> 358.325 | F42: =F36-(F17+F18+F19)-F39 -> 972.2
A43: Gross margin platform only | B43: % | C43: =C42/C36 -> 0.8193038 | D43: =D42/D36 -> 0.76746231 | E43: =E42/E36 -> 0.75436842 | F43: =F42/F36 -> 0.64813333
A44: GROSS PROFIT platform + AI Dispatcher | B44: $/mo | C44: =C36+C37-(C17+C18+C19)-C14-C40 -> 257.00769 | D44: =D36+D37-(D17+D18+D19)-D14-D40 -> 923.03844 | E44: =E36+E37-(E17+E18+E19)-E14-E40 -> 1871.6836 | F44: =F36+F37-(F17+F18+F19)-F14-F40 -> 5291.1094
A45: Gross margin platform + AI Dispatcher | B45: % | C45: =C44/(C36+C37) -> 0.76526825 | D45: =D44/(D36+D37) -> 0.71709015 | E45: =E44/(E36+E37) -> 0.67508876 | F45: =F44/(F36+F37) -> 0.5937728
...

Sheet Notes_Sources
A1: WHAT THIS MODEL IS: a gross-margin model (variable + allocated costs vs. price). It does NOT include engineering salaries, Lovable/Supabase platform plan costs beyond per-tenant allocation, sales & marketing/CAC, legal/compliance, churn, free trials, bad debt, taxes, one-time onboarding, or load board subscriptions (customers pay their own DAT/123Loadboard/Truckstop).
A2: STRESS ASSUMPTION: 4 loads/truck/week and 100% of loads booked via the AI Dispatcher (Abdel's assumption). Real adoption will likely be lower; AI revenue and cost scale together so AI margin % is unchanged, but platform-only revenue then dominates.
A3: VERIFIED PRICES (this session): Claude Haiku 5.5 $0.10/$0.50 per 1M tokens (<=100K prompts); Sonnet 5.5 $2/$10; Opus 5.5 $4/$20; Fable 5.1 $10/$50 (claude-api skill cached 2026-10-06).
A4: THIRD-PARTY / UNVERIFIED PRICES: Gemini 2.5 Flash $0.30/$2.50 (trackers citing ai.google.dev/gemini-api/docs/pricing); Vapi $0.05/min orchestration + STT/LLM/TTS/telephony separately, all-in $0.07-$0.31/min depending on source (zeeg.me, 11x.ai, techsy.io, speechify.ai); Twilio SMS ~$0.0079 + ~$0.003 carrier surcharge, voice ~$0.013-0.014/min, local number $1.15/mo, 10DLC campaign ~$10/mo + $4 brand/$15 campaign setup; Resend Pro $20/50k emails, overage $0.90/1k; Supabase Pro $25/mo + usage; Stripe ACH 0.8% cap $5, cards 2.9%+$0.30. Re-check each on the vendor's own pricing page before quoting externally.
A5: ESTIMATES TO MEASURE IN A PILOT: voice minutes per booked load, tokens per booked load, calls/emails per booked load, leads per month, support hours. These drive the result far more than token prices. Voice minutes x per-minute rate is ~86% of AI cost in the Base case; LLM tokens are ~9%.
A6: INFRA/SUPPORT per-tenant allocations are placeholders (see Assumptions) - replace with real figures once multi-tenant infrastructure and support process exist.
